Workbook

Sheet Inicio

Sheet Risco por Cooperativa
F4: PAPEL DE TRABALHO RSAC (Risco Social Ambiental e Climático) | O4: Retorno
C9: Elaborado por: Gleibson Carreiro de Sousa | F9: Data Base: | G9: 46023 | H9: Periodicadade: Mensal
C10: Revisado por: | F10: Data da Revisão
C13: RESULTADO
O14: Retorno
D15: ANÁLISE 01: Relatório de Risco por Cooperativa - Quantitativo
D17: QUANTITATIVO RSAC | F17: RELATÓRIO DE RISCO POR COOPERATIVA
F18: =EOMONTH(G9,-1)+1 -> 46023 | G18: a | H18: =EOMONTH(G9,0) -> 46053
D19: COOEPRATIVA | E19: AGÊNCIA | F19: BAIXO RISCO | G19: MÉDIO RISCO | H19: ALTO RISCO | I19: TOTAL
D20: Sicoob nova Central | E20: 1004 | F20: =SUMIFS('A1004'!L:L,'A1004'!$K:$K,">="&'Risco por Cooperativa'!$F$18,'A1004'!$K:$K,"<="&'Risco por Cooperativa'!$H$18) -> 0 | G20: =SUMIFS('A1004'!M:M,'A1004'!$K:$K,">="&'Risco por Cooperativa'!$F$18,'A1004'!$K:$K,"<="&'Risco por Cooperativa'!$H$18) -> 0 | H20: =SUMIFS('A1004'!N:N,'A1004'!$K:$K,">="&'Risco por Cooperativa'!$F$18,'A1004'!$K:$K,"<="&'Risco por Cooperativa'!$H$18) -> 0 | I20: =SUM(F20:H20) -> 0
D21: Sicoob Agrorural | E21: 3042 | F21: =SUMIFS('A3042'!L:L,'A3042'!$K:$K,">="&'Risco por Cooperativa'!$F$18,'A3042'!$K:$K,"<="&'Risco por Cooperativa'!$H$18) -> 18 | G21: =SUMIFS('A3042'!M:M,'A3042'!$K:$K,">="&'Risco por Cooperativa'!$F$18,'A3042'!$K:$K,"<="&'Risco por Cooperativa'!$H$18) -> 1 | H21: =SUMIFS('A3042'!N:N,'A3042'!$K:$K,">="&'Risco por Cooperativa'!$F$18,'A3042'!$K:$K,"<="&'Risco por Cooperativa'!$H$18) -> 1 | I21: =SUM(F21:H21) -> 20
D22: Sicoob Centro-Sul | E22: 3043 | F22: =SUMIFS('A3043'!L:L,'A3043'!$K:$K,">="&'Risco por Cooperativa'!$F$18,'A3043'!$K:$K,"<="&'Risco por Cooperativa'!$H$18) -> 10 | G22: =SUMIFS('A3043'!M:M,'A3043'!$K:$K,">="&'Risco por Cooperativa'!$F$18,'A3043'!$K:$K,"<="&'Risco por Cooperativa'!$H$18) -> 6 | H22: =SUMIFS('A3043'!N:N,'A3043'!$K:$K,">="&'Risco por Cooperativa'!$F$18,'A3043'!$K:$K,"<="&'Risco por Cooperativa'!$H$18) -> 2 | I22: =SUM(F22:H22) -> 18
D23: Sicoob Credi-Rural | E23: 3054 | F23: =SUMIFS('A3054'!L:L,'A3054'!$K:$K,">="&'Risco por Cooperativa'!$F$18,'A3054'!$K:$K,"<="&'Risco por Cooperativa'!$H$18) -> 70 | G23: =SUMIFS('A3054'!M:M,'A3054'!$K:$K,">="&'Risco por Cooperativa'!$F$18,'A3054'!$K:$K,"<="&'Risco por Cooperativa'!$H$18) -> 9 | H23: =SUMIFS('A3054'!N:N,'A3054'!$K:$K,">="&'Risco por Cooperativa'!$F$18,'A3054'!$K:$K,"<="&'Risco por Cooperativa'!$H$18) -> 9 | I23: =SUM(F23:H23) -> 88
D24: Siccob do Vale | E24: 3059 | F24: =SUMIFS('A3059'!L:L,'A3059'!$K:$K,">="&'Risco por Cooperativa'!$F$18,'A3059'!$K:$K,"<="&'Risco por Cooperativa'!$H$18) -> 27 | G24: =SUMIFS('A3059'!M:M,'A3059'!$K:$K,">="&'Risco por Cooperativa'!$F$18,'A3059'!$K:$K,"<="&'Risco por Cooperativa'!$H$18) -> 4 | H24: =SUMIFS('A3059'!N:N,'A3059'!$K:$K,">="&'Risco por Cooperativa'!$F$18,'A3059'!$K:$K,"<="&'Risco por Cooperativa'!$H$18) -> 1 | I24: =SUM(F24:H24) -> 32
D25: Sicoob Palmeiras | E25: 3060 | F25: =SUMIFS('A3060'!L:L,'A3060'!$K:$K,">="&'Risco por Cooperativa'!$F$18,'A3060'!$K:$K,"<="&'Risco por Cooperativa'!$H$18) -> 16 | G25: =SUMIFS('A3060'!M:M,'A3060'!$K:$K,">="&'Risco por Cooperativa'!$F$18,'A3060'!$K:$K,"<="&'Risco por Cooperativa'!$H$18) -> 0 | H25: =SUMIFS('A3060'!N:N,'A3060'!$K:$K,">="&'Risco por Cooperativa'!$F$18,'A3060'!$K:$K,"<="&'Risco por Cooperativa'!$H$18) -> 1 | I25: =SUM(F25:H25) -> 17
D26: Sicoob Credijur | E26: 3233 | F26: =SUMIFS('A3233'!L:L,'A3233'!$K:$K,">="&'Risco por Cooperativa'!$F$18,'A3233'!$K:$K,"<="&'Risco por Cooperativa'!$H$18) -> 2 | G26: =SUMIFS('A3233'!M:M,'A3233'!$K:$K,">="&'Risco por Cooperativa'!$F$18,'A3233'!$K:$K,"<="&'Risco por Cooperativa'!$H$18) -> 0 | H26: =SUMIFS('A3233'!N:N,'A3233'!$K:$K,">="&'Risco por Cooperativa'!$F$18,'A3233'!$K:$K,"<="&'Risco por Cooperativa'!$H$18) -> 0 | I26: =SUM(F26:H26) -> 2
D27: Sicoob Credicapa | E27: 3261 | F27: =SUMIFS('A3261'!L:L,'A3261'!$K:$K,">="&'Risco por Cooperativa'!$F$18,'A3261'!$K:$K,"<="&'Risco por Cooperativa'!$H$18) -> 7 | G27: =SUMIFS('A3261'!M:M,'A3261'!$K:$K,">="&'Risco por Cooperativa'!$F$18,'A3261'!$K:$K,"<="&'Risco por Cooperativa'!$H$18) -> 0 | H27: =SUMIFS('A3261'!N:N,'A3261'!$K:$K,">="&'Risco por Cooperativa'!$F$18,'A3261'!$K:$K,"<="&'Risco por Cooperativa'!$H$18) -> 1 | I27: =SUM(F27:H27) -> 8
D28: Sicoob Tocantins | E28: 3263 | F28: =SUMIFS('A3263'!L:L,'A3263'!$K:$K,">="&'Risco por Cooperativa'!$F$18,'A3263'!$K:$K,"<="&'Risco por Cooperativa'!$H$18) -> 10 | G28: =SUMIFS('A3263'!M:M,'A3263'!$K:$K,">="&'Risco por Cooperativa'!$F$18,'A3263'!$K:$K,"<="&'Risco por Cooperativa'!$H$18) -> 0 | H28: =SUMIFS('A3263'!N:N,'A3263'!$K:$K,">="&'Risco por Cooperativa'!$F$18,'A3263'!$K:$K,"<="&'Risco por Cooperativa'!$H$18) -> 2 | I28: =SUM(F28:H28) -> 12
D29: Sicoob Cerrado | E29: 3320 | F29: =SUMIFS('A3320'!L:L,'A3320'!$K:$K,">="&'Risco por Cooperativa'!$F$18,'A3320'!$K:$K,"<="&'Risco por Cooperativa'!$H$18) -> 8 | G29: =SUMIFS('A3320'!M:M,'A3320'!$K:$K,">="&'Risco por Cooperativa'!$F$18,'A3320'!$K:$K,"<="&'Risco por Cooperativa'!$H$18) -> 1 | H29: =SUMIFS('A3320'!N:N,'A3320'!$K:$K,">="&'Risco por Cooperativa'!$F$18,'A3320'!$K:$K,"<="&'Risco por Cooperativa'!$H$18) -> 2 | I29: =SUM(F29:H29) -> 11
D30: Sicoob Emprecred | E30: 3332 | F30: =SUMIFS('A3332'!L:L,'A3332'!$K:$K,">="&'Risco por Cooperativa'!$F$18,'A3332'!$K:$K,"<="&'Risco por Cooperativa'!$H$18) -> 8 | G30: =SUMIFS('A3332'!M:M,'A3332'!$K:$K,">="&'Risco por Cooperativa'!$F$18,'A3332'!$K:$K,"<="&'Risco por Cooperativa'!$H$18) -> 0 | H30: =SUMIFS('A3332'!N:N,'A3332'!$K:$K,">="&'Risco por Cooperativa'!$F$18,'A3332'!$K:$K,"<="&'Risco por Cooperativa'!$H$18) -> 4 | I30: =SUM(F30:H30) -> 12
D31: Sicob Secovicred | E31: 3333 | F31: =SUMIFS('A3333'!L:L,'A3333'!$K:$K,">="&'Risco por Cooperativa'!$F$18,'A3333'!$K:$K,"<="&'Risco por Cooperativa'!$H$18) -> 22 | G31: =SUMIFS('A3333'!M:M,'A3333'!$K:$K,">="&'Risco por Cooperativa'!$F$18,'A3333'!$K:$K,"<="&'Risco por Cooperativa'!$H$18) -> 1 | H31: =SUMIFS('A3333'!N:N,'A3333'!$K:$K,">="&'Risco por Cooperativa'!$F$18,'A3333'!$K:$K,"<="&'Risco por Cooperativa'!$H$18) -> 4 | I31: =SUM(F31:H31) -> 27
D32: Sicoob Juriscred | E32: 3348 | F32: =SUMIFS('A3348'!L:L,'A3348'!$K:$K,">="&'Risco por Cooperativa'!$F$18,'A3348'!$K:$K,"<="&'Risco por Cooperativa'!$H$18) -> 2 | G32: =SUMIFS('A3348'!M:M,'A3348'!$K:$K,">="&'Risco por Cooperativa'!$F$18,'A3348'!$K:$K,"<="&'Risco por Cooperativa'!$H$18) -> 0 | H32: =SUMIFS('A3348'!N:N,'A3348'!$K:$K,">="&'Risco por Cooperativa'!$F$18,'A3348'!$K:$K,"<="&'Risco por Cooperativa'!$H$18) -> 0 | I32: =SUM(F32:H32) -> 2
D33: Sicoob Credicer | E33: 3349 | F33: =SUMIFS('A3349'!L:L,'A3349'!$K:$K,">="&'Risco por Cooperativa'!$F$18,'A3349'!$K:$K,"<="&'Risco por Cooperativa'!$H$18) -> 3 | G33: =SUMIFS('A3349'!M:M,'A3349'!$K:$K,">="&'Risco por Cooperativa'!$F$18,'A3349'!$K:$K,"<="&'Risco por Cooperativa'!$H$18) -> 0 | H33: =SUMIFS('A3349'!N:N,'A3349'!$K:$K,">="&'Risco por Cooperativa'!$F$18,'A3349'!$K:$K,"<="&'Risco por Cooperativa'!$H$18) -> 1 | I33: =SUM(F33:H33) -> 4
D34: Sicoob Crediadag | E34: 3351 | F34: =SUMIFS('A3351'!L:L,'A3351'!$K:$K,">="&'Risco por Cooperativa'!$F$18,'A3351'!$K:$K,"<="&'Risco por Cooperativa'!$H$18) -> 5 | G34: =SUMIFS('A3351'!M:M,'A3351'!$K:$K,">="&'Risco por Cooperativa'!$F$18,'A3351'!$K:$K,"<="&'Risco por Cooperativa'!$H$18) -> 0 | H34: =SUMIFS('A3351'!N:N,'A3351'!$K:$K,">="&'Risco por Cooperativa'!$F$18,'A3351'!$K:$K,"<="&'Risco por Cooperativa'!$H$18) -> 1 | I34: =SUM(F34:H34) -> 6
D35: Sicoob Empresarial GO | E35: 3343 | F35: =SUMIFS('A3343'!L:L,'A3343'!$K:$K,">="&'Risco por Cooperativa'!$F$18,'A3343'!$K:$K,"<="&'Risco por Cooperativa'!$H$18) -> 9 | G35: =SUMIFS('A3343'!M:M,'A3343'!$K:$K,">="&'Risco por Cooperativa'!$F$18,'A3343'!$K:$K,"<="&'Risco por Cooperativa'!$H$18) -> 1 | H35: =SUMIFS('A3343'!N:N,'A3343'!$K:$K,">="&'Risco por Cooperativa'!$F$18,'A3343'!$K:$K,"<="&'Risco por Cooperativa'!$H$18) -> 0 | I35: =SUM(F35:H35) -> 10
D36: Sicoob Cooprem | E36: 3350 | F36: =SUMIFS('A3350'!L:L,'A3350'!$K:$K,">="&'Risco por Cooperativa'!$F$18,'A3350'!$K:$K,"<="&'Risco por Cooperativa'!$H$18) -> 10 | G36: =SUMIFS('A3350'!M:M,'A3350'!$K:$K,">="&'Risco por Cooperativa'!$F$18,'A3350'!$K:$K,"<="&'Risco por Cooperativa'!$H$18) -> 1 | H36: =SUMIFS('A3350'!N:N,'A3350'!$K:$K,">="&'Risco por Cooperativa'!$F$18,'A3350'!$K:$K,"<="&'Risco por Cooperativa'!$H$18) -> 1 | I36: =SUM(F36:H36) -> 12
D37: Sicoob Credi-Comigo | E37: 3336 | F37: =SUMIFS('A3336'!L:L,'A3336'!$K:$K,">="&'Risco por Cooperativa'!$F$18,'A3336'!$K:$K,"<="&'Risco por Cooperativa'!$H$18) -> 0 | G37: =SUMIFS('A3336'!M:M,'A3336'!$K:$K,">="&'Risco por Cooperativa'!$F$18,'A3336'!$K:$K,"<="&'Risco por Cooperativa'!$H$18) -> 0 | H37: =SUMIFS('A3336'!N:N,'A3336'!$K:$K,">="&'Risco por Cooperativa'!$F$18,'A3336'!$K:$K,"<="&'Risco por Cooperativa'!$H$18) -> 0 | I37: =SUM(F37:H37) -> 0
D38: Sicoob Credigóias | E38: 3058 | F38: =SUMIFS('A3058'!L:L,'A3058'!$K:$K,">="&'Risco por Cooperativa'!$F$18,'A3058'!$K:$K,"<="&'Risco por Cooperativa'!$H$18) -> 3 | G38: =SUMIFS('A3058'!M:M,'A3058'!$K:$K,">="&'Risco por Cooperativa'!$F$18,'A3058'!$K:$K,"<="&'Risco por Cooperativa'!$H$18) -> 2 | H38: =SUMIFS('A3058'!N:N,'A3058'!$K:$K,">="&'Risco por Cooperativa'!$F$18,'A3058'!$K:$K,"<="&'Risco por Cooperativa'!$H$18) -> 1 | I38: =SUM(F38:H38) -> 6
D39: Sicoob Coopercred | E39: 3055 | F39: =SUMIFS('A3055'!L:L,'A3055'!$K:$K,">="&'Risco por Cooperativa'!$F$18,'A3055'!$K:$K,"<="&'Risco por Cooperativa'!$H$18) -> 7 | G39: =SUMIFS('A3055'!M:M,'A3055'!$K:$K,">="&'Risco por Cooperativa'!$F$18,'A3055'!$K:$K,"<="&'Risco por Cooperativa'!$H$18) -> 0 | H39: =SUMIFS('A3055'!N:N,'A3055'!$K:$K,">="&'Risco por Cooperativa'!$F$18,'A3055'!$K:$K,"<="&'Risco por Cooperativa'!$H$18) -> 0 | I39: =SUM(F39:H39) -> 7
D40: Sicoob Unicidades | E40: 5014 | F40: =SUMIFS('A5014'!L:L,'A5014'!$K:$K,">="&'Risco por Cooperativa'!$F$18,'A5014'!$K:$K,"<="&'Risco por Cooperativa'!$H$18) -> 25 | G40: =SUMIFS('A5014'!M:M,'A5014'!$K:$K,">="&'Risco por Cooperativa'!$F$18,'A5014'!$K:$K,"<="&'Risco por Cooperativa'!$H$18) -> 1 | H40: =SUMIFS('A5014'!N:N,'A5014'!$K:$K,">="&'Risco por Cooperativa'!$F$18,'A5014'!$K:$K,"<="&'Risco por Cooperativa'!$H$18) -> 1 | I40: =SUM(F40:H40) -> 27
D41: Sicoob Mineiros | E41: 3056 | F41: =SUMIFS('A3056'!L:L,'A3056'!$K:$K,">="&'Risco por Cooperativa'!$F$18,'A3056'!$K:$K,"<="&'Risco por Cooperativa'!$H$18) -> 12 | G41: =SUMIFS('A3056'!M:M,'A3056'!$K:$K,">="&'Risco por Cooperativa'!$F$18,'A3056'!$K:$K,"<="&'Risco por Cooperativa'!$H$18) -> 0 | H41: =SUMIFS('A3056'!N:N,'A3056'!$K:$K,">="&'Risco por Cooperativa'!$F$18,'A3056'!$K:$K,"<="&'Risco por Cooperativa'!$H$18) -> 2 | I41: =SUM(F41:H41) -> 14
D42: Sicoob Centro Oeste BR | E42: 3300 | F42: =SUMIFS('A3300'!L:L,'A3300'!$K:$K,">="&'Risco por Cooperativa'!$F$18,'A3300'!$K:$K,"<="&'Risco por Cooperativa'!$H$18) -> 2 | G42: =SUMIFS('A3300'!M:M,'A3300'!$K:$K,">="&'Risco por Cooperativa'!$F$18,'A3300'!$K:$K,"<="&'Risco por Cooperativa'!$H$18) -> 1 | H42: =SUMIFS('A3300'!N:N,'A3300'!$K:$K,">="&'Risco por Cooperativa'!$F$18,'A3300'!$K:$K,"<="&'Risco por Cooperativa'!$H$18) -> 2 | I42: =SUM(F42:H42) -> 5
D43: Sicoob Executivo | E43: 4001 | F43: =SUMIFS('A4001'!L:L,'A4001'!$K:$K,">="&'Risco por Cooperativa'!$F$18,'A4001'!$K:$K,"<="&'Risco por Cooperativa'!$H$18) -> 0 | G43: =SUMIFS('A4001'!M:M,'A4001'!$K:$K,">="&'Risco por Cooperativa'!$F$18,'A4001'!$K:$K,"<="&'Risco por Cooperativa'!$H$18) -> 0 | H43: =SUMIFS('A4001'!N:N,'A4001'!$K:$K,">="&'Risco por Cooperativa'!$F$18,'A4001'!$K:$K,"<="&'Risco por Cooperativa'!$H$18) -> 0 | I43: =SUM(F43:H43) -> 0
D44: Sicoob Judiciário | E44: 4002 | F44: =SUMIFS('A4002'!L:L,'A4002'!$K:$K,">="&'Risco por Cooperativa'!$F$18,'A4002'!$K:$K,"<="&'Risco por Cooperativa'!$H$18) -> 0 | G44: =SUMIFS('A4002'!M:M,'A4002'!$K:$K,">="&'Risco por Cooperativa'!$F$18,'A4002'!$K:$K,"<="&'Risco por Cooperativa'!$H$18) -> 0 | H44: =SUMIFS('A4002'!N:N,'A4002'!$K:$K,">="&'Risco por Cooperativa'!$F$18,'A4002'!$K:$K,"<="&'Risco por Cooperativa'!$H$18) -> 0 | I44: =SUM(F44:H44) -> 0
D45: Sicoob Credijustra | E45: 4041 | F45: =SUMIFS('A4041'!L:L,'A4041'!$K:$K,">="&'Risco por Cooperativa'!$F$18,'A4041'!$K:$K,"<="&'Risco por Cooperativa'!$H$18) -> 0 | G45: =SUMIFS('A4041'!M:M,'A4041'!$K:$K,">="&'Risco por Cooperativa'!$F$18,'A4041'!$K:$K,"<="&'Risco por Cooperativa'!$H$18) -> 0 | H45: =SUMIFS('A4041'!N:N,'A4041'!$K:$K,">="&'Risco por Cooperativa'!$F$18,'A4041'!$K:$K,"<="&'Risco por Cooperativa'!$H$18) -> 0 | I45: =SUM(F45:H45) -> 0
D46: Sicoob Credibrasília | E46: 4155 | F46: =SUMIFS('A4155'!L:L,'A4155'!$K:$K,">="&'Risco por Cooperativa'!$F$18,'A4155'!$K:$K,"<="&'Risco por Cooperativa'!$H$18) -> 6 | G46: =SUMIFS('A4155'!M:M,'A4155'!$K:$K,">="&'Risco por Cooperativa'!$F$18,'A4155'!$K:$K,"<="&'Risco por Cooperativa'!$H$18) -> 5 | H46: =SUMIFS('A4155'!N:N,'A4155'!$K:$K,">="&'Risco por Cooperativa'!$F$18,'A4155'!$K:$K,"<="&'Risco por Cooperativa'!$H$18) -> 0 | I46: =SUM(F46:H46) -> 11
D47: Sicoob Crediembrapa | E47: 4198 | F47: =SUMIFS('A4198'!L:L,'A4198'!$K:$K,">="&'Risco por Cooperativa'!$F$18,'A4198'!$K:$K,"<="&'Risco por Cooperativa'!$H$18) -> 11 | G47: =SUMIFS('A4198'!M:M,'A4198'!$K:$K,">="&'Risco por Cooperativa'!$F$18,'A4198'!$K:$K,"<="&'Risco por Cooperativa'!$H$18) -> 0 | H47: =SUMIFS('A4198'!N:N,'A4198'!$K:$K,">="&'Risco por Cooperativa'!$F$18,'A4198'!$K:$K,"<="&'Risco por Cooperativa'!$H$18) -> 0 | I47: =SUM(F47:H47) -> 11
D48: Sicoob Credfaz | E48: 4221 | F48: =SUMIFS('A4221'!L:L,'A4221'!$K:$K,">="&'Risco por Cooperativa'!$F$18,'A4221'!$K:$K,"<="&'Risco por Cooperativa'!$H$18) -> 2 | G48: =SUMIFS('A4221'!M:M,'A4221'!$K:$K,">="&'Risco por Cooperativa'!$F$18,'A4221'!$K:$K,"<="&'Risco por Cooperativa'!$H$18) -> 0 | H48: =SUMIFS('A4221'!N:N,'A4221'!$K:$K,">="&'Risco por Cooperativa'!$F$18,'A4221'!$K:$K,"<="&'Risco por Cooperativa'!$H$18) -> 0 | I48: =SUM(F48:H48) -> 2
D49: Sicoob Cooperplan Credsef | E49: 4278 | F49: =SUMIFS('A4278'!L:L,'A4278'!$K:$K,">="&'Risco por Cooperativa'!$F$18,'A4278'!$K:$K,"<="&'Risco por Cooperativa'!$H$18) -> 0 | G49: =SUMIFS('A4278'!M:M,'A4278'!$K:$K,">="&'Risco por Cooperativa'!$F$18,'A4278'!$K:$K,"<="&'Risco por Cooperativa'!$H$18) -> 0 | H49: =SUMIFS('A4278'!N:N,'A4278'!$K:$K,">="&'Risco por Cooperativa'!$F$18,'A4278'!$K:$K,"<="&'Risco por Cooperativa'!$H$18) -> 1 | I49: =SUM(F49:H49) -> 1
D50: Sicoob BRMil | E50: 4332 | F50: =SUMIFS('A4332'!L:L,'A4332'!$K:$K,">="&'Risco por Cooperativa'!$F$18,'A4332'!$K:$K,"<="&'Risco por Cooperativa'!$H$18) -> 1 | G50: =SUMIFS('A4332'!M:M,'A4332'!$K:$K,">="&'Risco por Cooperativa'!$F$18,'A4332'!$K:$K,"<="&'Risco por Cooperativa'!$H$18) -> 0 | H50: =SUMIFS('A4332'!N:N,'A4332'!$K:$K,">="&'Risco por Cooperativa'!$F$18,'A4332'!$K:$K,"<="&'Risco por Cooperativa'!$H$18) -> 0 | I50: =SUM(F50:H50) -> 1
...

Sheet Resposta do quest. Cooperados
F4: PAPEL DE TRABALHO RSAC (Risco Social Ambiental e Climático) | O4: Retorno
C9: Elaborado por: Gleibson Carreiro de Sousa | F9: Data Base: | G9: 46023 | H9: Periodicadade: Mensal
C10: Revisado por: | F10: Data da Revisão
C13: RESULTADO
D14: ANÁLISE 02: Análise das respostas fornecidas no questionário de RSAC.
D16: QUANTITATIVO DA AMOSTRA | F16: RELATÓRIO DE ANÁLISE DAS RESPOSTAS DO QUESTIONÁRIO POR COOPERATIVA
D17: COOEPRATIVA | E17: AGÊNCIA | F17: =EOMONTH(G9,-1)+1 -> 46023 | G17: a | H17: =EOMONTH(G9,0) -> 46053 | O17: Retorno
D18: COOEPRATIVA | E18: AGÊNCIA | F18: Cooperados analisados | G18: Quantos NÃO apresentaram pendências? | H18: Quantos apresentaram pendências? | I18: % de pendência
D19: Sicoob nova Central | E19: 1004 | F19: =SUM('A1004'!$C$4:$E$4) -> 0 | G19: =IFERROR((F19-H19),F19) -> 0 | H19: =COUNTIF('A1004'!$AO:$AO,"Cooperado COM perguntas a serem evidenciadas") -> 0 | I19: =IFERROR((H19/F19),0) -> 0
D20: Sicoob Agrorural | E20: 3042 | F20: =SUM('A3042'!$C$4:$E$4) -> 20 | G20: =IFERROR((F20-H20),F20) -> 20 | H20: =COUNTIF('A3042'!$AO:$AO,"Cooperado COM perguntas a serem evidenciadas") -> 0 | I20: =IFERROR((H20/F20),0) -> 0
D21: Sicoob Centro-Sul | E21: 3043 | F21: =SUM('A3043'!$C$4:$E$4) -> 18 | G21: =IFERROR((F21-H21),F21) -> 13 | H21: =COUNTIF('A3043'!$AO:$AO,"Cooperado COM perguntas a serem evidenciadas") -> 5 | I21: =IFERROR((H21/F21),0) -> 0.27777778
D22: Sicoob Credi-Rural | E22: 3054 | F22: =SUM('A3054'!$C$4:$E$4) -> 88 | G22: =IFERROR((F22-H22),F22) -> 83 | H22: =COUNTIF('A3054'!$AO:$AO,"Cooperado COM perguntas a serem evidenciadas") -> 5 | I22: =IFERROR((H22/F22),0) -> 0.056818182
D23: Siccob do Vale | E23: 3059 | F23: =SUM('A3059'!$C$4:$E$4) -> 32 | G23: =IFERROR((F23-H23),F23) -> 15 | H23: =COUNTIF('A3059'!$AO:$AO,"Cooperado COM perguntas a serem evidenciadas") -> 17 | I23: =IFERROR((H23/F23),0) -> 0.53125
D24: Sicoob Palmeiras | E24: 3060 | F24: =SUM('A3060'!$C$4:$E$4) -> 17 | G24: =IFERROR((F24-H24),F24) -> 15 | H24: =COUNTIF('A3060'!$AO:$AO,"Cooperado COM perguntas a serem evidenciadas") -> 2 | I24: =IFERROR((H24/F24),0) -> 0.11764706
D25: Sicoob Credijur | E25: 3233 | F25: =SUM('A3233'!$C$4:$E$4) -> 2 | G25: =IFERROR((F25-H25),F25) -> 2 | H25: =COUNTIF('A3233'!$AO:$AO,"Cooperado COM perguntas a serem evidenciadas") -> 0 | I25: =IFERROR((H25/F25),0) -> 0
D26: Sicoob Credicapa | E26: 3261 | F26: =SUM('A3261'!$C$4:$E$4) -> 8 | G26: =IFERROR((F26-H26),F26) -> 5 | H26: =COUNTIF('A3261'!$AO:$AO,"Cooperado COM perguntas a serem evidenciadas") -> 3 | I26: =IFERROR((H26/F26),0) -> 0.375
D27: Sicoob Tocantins | E27: 3263 | F27: =SUM('A3263'!$C$4:$E$4) -> 12 | G27: =IFERROR((F27-H27),F27) -> 6 | H27: =COUNTIF('A3263'!$AO:$AO,"Cooperado COM perguntas a serem evidenciadas") -> 6 | I27: =IFERROR((H27/F27),0) -> 0.5
D28: Sicoob Cerrado | E28: 3320 | F28: =SUM('A3320'!$C$4:$E$4) -> 11 | G28: =IFERROR((F28-H28),F28) -> 10 | H28: =COUNTIF('A3320'!$AO:$AO,"Cooperado COM perguntas a serem evidenciadas") -> 1 | I28: =IFERROR((H28/F28),0) -> 0.090909091
D29: Sicoob Emprecred | E29: 3332 | F29: =SUM('A3332'!$C$4:$E$4) -> 12 | G29: =IFERROR((F29-H29),F29) -> 12 | H29: =COUNTIF('A3332'!$AO:$AO,"Cooperado COM perguntas a serem evidenciadas") -> 0 | I29: =IFERROR((H29/F29),0) -> 0
D30: Sicob Secovicred | E30: 3333 | F30: =SUM('A3333'!$C$4:$E$4) -> 27 | G30: =IFERROR((F30-H30),F30) -> 26 | H30: =COUNTIF('A3333'!$AO:$AO,"Cooperado COM perguntas a serem evidenciadas") -> 1 | I30: =IFERROR((H30/F30),0) -> 0.037037037
D31: Sicoob Juriscredcelg | E31: 3348 | F31: =SUM('A3348'!$C$4:$E$4) -> 2 | G31: =IFERROR((F31-H31),F31) -> 1 | H31: =COUNTIF('A3348'!$AO:$AO,"Cooperado COM perguntas a serem evidenciadas") -> 1 | I31: =IFERROR((H31/F31),0) -> 0.5
D32: Sicoob Credicer | E32: 3349 | F32: =SUM('A3349'!$C$4:$E$4) -> 4 | G32: =IFERROR((F32-H32),F32) -> 2 | H32: =COUNTIF('A3349'!$AO:$AO,"Cooperado COM perguntas a serem evidenciadas") -> 2 | I32: =IFERROR((H32/F32),0) -> 0.5
D33: Sicoob Crediadag | E33: 3351 | F33: =SUM('A3351'!$C$4:$E$4) -> 6 | G33: =IFERROR((F33-H33),F33) -> 5 | H33: =COUNTIF('A3351'!$AO:$AO,"Cooperado COM perguntas a serem evidenciadas") -> 1 | I33: =IFERROR((H33/F33),0) -> 0.16666667
D34: Sicoob Executivo | E34: 4001 | F34: =SUM('A4001'!$C$4:$E$4) -> 0 | G34: =IFERROR((F34-H34),F34) -> 0 | H34: =COUNTIF('A4001'!$AO:$AO,"Cooperado COM perguntas a serem evidenciadas") -> 0 | I34: =IFERROR((H34/F34),0) -> 0
D35: Sicoob Judiciário | E35: 4002 | F35: =SUM('A4002'!$C$4:$E$4) -> 0 | G35: =IFERROR((F35-H35),F35) -> 0 | H35: =COUNTIF('A4002'!$AO:$AO,"Cooperado COM perguntas a serem evidenciadas") -> 0 | I35: =IFERROR((H35/F35),0) -> 0
D36: Sicoob Credijustra | E36: 4041 | F36: =SUM('A4041'!$C$4:$E$4) -> 0 | G36: =IFERROR((F36-H36),F36) -> 0 | H36: =COUNTIF('A4041'!$AO:$AO,"Cooperado COM perguntas a serem evidenciadas") -> 0 | I36: =IFERROR((H36/F36),0) -> 0
D37: Sicoob Credibrasília | E37: 4155 | F37: =SUM('A4155'!$C$4:$E$4) -> 11 | G37: =IFERROR((F37-H37),F37) -> 8 | H37: =COUNTIF('A4155'!$AO:$AO,"Cooperado COM perguntas a serem evidenciadas") -> 3 | I37: =IFERROR((H37/F37),0) -> 0.27272727
D38: Sicoob Crediembrapa | E38: 4198 | F38: =SUM('A4198'!$C$4:$E$4) -> 11 | G38: =IFERROR((F38-H38),F38) -> 10 | H38: =COUNTIF('A4198'!$AO:$AO,"Cooperado COM perguntas a serem evidenciadas") -> 1 | I38: =IFERROR((H38/F38),0) -> 0.090909091
D39: Sicoob Credfaz | E39: 4221 | F39: =SUM('A4221'!$C$4:$E$4) -> 2 | G39: =IFERROR((F39-H39),F39) -> 2 | H39: =COUNTIF('A4221'!$AO:$AO,"Cooperado COM perguntas a serem evidenciadas") -> 0 | I39: =IFERROR((H39/F39),0) -> 0
D40: Sicoob Cooperplan Credsef | E40: 4278 | F40: =SUM('A4278'!$C$4:$E$4) -> 1 | G40: =IFERROR((F40-H40),F40) -> 1 | H40: =COUNTIF('A4278'!$AO:$AO,"Cooperado COM perguntas a serem evidenciadas") -> 0 | I40: =IFERROR((H40/F40),0) -> 0
D41: Sicoob Dfmil | E41: 4332 | F41: =SUM('A4332'!$C$4:$E$4) -> 1 | G41: =IFERROR((F41-H41),F41) -> 1 | H41: =COUNTIF('A4332'!$AO:$AO,"Cooperado COM perguntas a serem evidenciadas") -> 0 | I41: =IFERROR((H41/F41),0) -> 0
D42: Sicoob Empresarial | E42: 4364 | F42: =SUM('A4364'!$C$4:$E$4) -> 0 | G42: =IFERROR((F42-H42),F42) -> 0 | H42: =COUNTIF('A4364'!$AO:$AO,"Cooperado COM perguntas a serem evidenciadas") -> 0 | I42: =IFERROR((H42/F42),0) -> 0
D44: TOTAL | H44: =SUM(H19:H43) -> 48
B48: Apresentamos abaixo as perguntas que são avaliadas quanto à conformidade do preenchimento do questionário, assim como a inclusão de evidências referentes a elas na plataforma de Atendimento. Apresentamos abaixo, as perguntas que são avaliadas quanto a conformidade do preenchimento do questionário, bem como a inclusão de evidências quanto a elas na plataforma de Atendimento.
B51: Pergunta 01: A atividade está sujeita ao licenciamento ambiental conforme Resolução CONAMA n° 237/1997 ou normativo estadual / Municipal, se houver? Se sim, declara possuir o licenciamento necessário vigente?
C54: Para atestar a conformidade da resposta, checamos o CNAE da empresa com a resposta fornecida.
B56: Pergunta 02: Declara que há a compensação da Reserva Legal em outra Propriedade?
C59: Verificamos no Sistema AGROTOUS, se há compensação de Reserva Legal cruzando a informação com a resposta fornecida.
B61: Pergunta 03: O uso da água na área de produção e/ou construção está em conformidade com as normas de utilização de recursos hídricos (Lei n° 9.433/1997?)?
C64: A Lei n° 9.433/1997, apresenta as atividades que necessitam ou podem optar pela dispensa da outorga de água. Fazemos a verificação.
...

Sheet Análise Fornecedores
F4: PAPEL DE TRABALHO RSAC (Risco Social Ambiental e Climático) | R4: Retorno
C9: Elaborado por: Gleibson Carreiro de Sousa | F9: Data Base: | G9: 46023 | K9: Periodicadade: Mensal
C10: Revisado por: | F10: Data da Revisão
C13: RESULTADO
D14: ANÁLISE 03 e 04: Análise dos fornecedores e prestadores de serviços de RSAC e enquadramento dos setores sensíveis.
D16: QUANTITATIVO | F16: RELATÓRIO DE ANÁLISE DOS FORNECEDORES E DOS SETORES SENSÍVEIS
D17: COOEPRATIVA | E17: AGÊNCIA | F17: =EOMONTH(G9,-1)+1 -> 46023 | J17: a | K17: =EOMONTH(G9,0) -> 46053
F18: Análise dos fornecedores e prestadores de serviços | K18: Análise de enquadramento nos setores sensíveis de RSAC - Limite 15%
G19: RISCO
D20: COOEPRATIVA | E20: AGÊNCIA | F20: Quantitativo de Fornecedores Cadastrados | G20: Baixo | H20: Médio | I20: Alto | J20: Qtde enquadrada na Lista Suja do (MTE) | K20: Resultado de sensibilidade | L20: situação
D21: Sicoob nova Central | E21: 1004 | F21: {=IFERROR(SUMPRODUCT((FREQUENCY(IF(For_1004!D4:D33<>"",MATCH(For_1004!D4:D33,For_1004!D4:D33,0)),ROW(For_1004!D4:D33)-ROW(For_1004!D4)+1)>0)*1),0)} -> 0 | G21: =COUNTIF(For_1004!$B$4:$B$33,'Análise Fornecedores'!G20) -> 0 | H21: =COUNTIF(For_1004!$B$4:$B$33,'Análise Fornecedores'!H20) -> 0 | I21: =COUNTIF(For_1004!$B$4:$B$33,'Análise Fornecedores'!I20) -> 0 | J21: =COUNTIF(For_1004!$J$4:$J$33,"Sim") -> 0 | K21: ='A1004'!$B$7 -> 0 | L21: ='A1004'!$D$7 -> ENQUADRADO
D22: Sicoob Agrorural | E22: 3042 | F22: {=IFERROR(SUMPRODUCT((FREQUENCY(IF(For_3042!D4:D33<>"",MATCH(For_3042!D4:D33,For_3042!D4:D33,0)),ROW(For_3042!D4:D33)-ROW(For_3042!D4)+1)>0)*1),0)} -> 0 | G22: =COUNTIF(For_3042!$B$4:$B$33,'Análise Fornecedores'!G20) -> 0 | H22: =COUNTIF(For_3042!$B$4:$B$33,'Análise Fornecedores'!H20) -> 0 | I22: =COUNTIF(For_3042!$B$4:$B$33,'Análise Fornecedores'!I20) -> 0 | J22: =COUNTIF(For_3042!$J$4:$J$33,"Sim") -> 0 | K22: ='A3042'!$B$7 -> 0.00013757353 | L22: ='A3042'!$D$7 -> ENQUADRADO
D23: Sicoob Centro-Sul | E23: 3043 | F23: {=IFERROR(SUMPRODUCT((FREQUENCY(IF(For_3043!D4:D33<>"",MATCH(For_3043!D4:D33,For_3043!D4:D33,0)),ROW(For_3043!D4:D33)-ROW(For_3043!D4)+1)>0)*1),0)} -> 0 | G23: =COUNTIF(For_3043!$B$4:$B$33,'Análise Fornecedores'!G20) -> 0 | H23: =COUNTIF(For_3043!$B$4:$B$33,'Análise Fornecedores'!H20) -> 0 | I23: =COUNTIF(For_3043!$B$4:$B$33,'Análise Fornecedores'!I20) -> 0 | J23: =COUNTIF(For_3043!$J$4:$J$33,"Sim") -> 0 | K23: ='A3043'!$B$7 -> 0 | L23: ='A3043'!$D$7 -> ENQUADRADO
D24: Sicoob Credi-Rural | E24: 3054 | F24: {=IFERROR(SUMPRODUCT((FREQUENCY(IF(For_3054!D4:D33<>"",MATCH(For_3054!D4:D33,For_3054!D4:D33,0)),ROW(For_3054!D4:D33)-ROW(For_3054!D4)+1)>0)*1),0)} -> 3 | G24: =COUNTIF(For_3054!$B$4:$B$33,'Análise Fornecedores'!G20) -> 3 | H24: =COUNTIF(For_3054!$B$4:$B$33,'Análise Fornecedores'!H20) -> 0 | I24: =COUNTIF(For_3054!$B$4:$B$33,'Análise Fornecedores'!I20) -> 0 | J24: =COUNTIF(For_3054!$J$4:$J$33,"Sim") -> 0 | K24: ='A3054'!$B$7 -> 0.00093732831 | L24: ='A3054'!$D$7 -> ENQUADRADO
D25: Siccob do Vale | E25: 3059 | F25: {=IFERROR(SUMPRODUCT((FREQUENCY(IF(For_3059!D4:D33<>"",MATCH(For_3059!D4:D33,For_3059!D4:D33,0)),ROW(For_3059!D4:D33)-ROW(For_3059!D4)+1)>0)*1),0)} -> 0 | G25: =COUNTIF(For_3059!$B$4:$B$33,'Análise Fornecedores'!G20) -> 0 | H25: =COUNTIF(For_3059!$B$4:$B$33,'Análise Fornecedores'!H20) -> 0 | I25: =COUNTIF(For_3059!$B$4:$B$33,'Análise Fornecedores'!I20) -> 0 | J25: =COUNTIF(For_3059!$J$4:$J$33,"Sim") -> 0 | K25: ='A3059'!$B$7 -> 0.0025731036 | L25: ='A3059'!$D$7 -> ENQUADRADO
D26: Sicoob Palmeiras | E26: 3060 | F26: {=IFERROR(SUMPRODUCT((FREQUENCY(IF(For_3060!D4:D33<>"",MATCH(For_3060!D4:D33,For_3060!D4:D33,0)),ROW(For_3060!D4:D33)-ROW(For_3060!D4)+1)>0)*1),0)} -> 0 | G26: =COUNTIF(For_3060!$B$4:$B$33,'Análise Fornecedores'!G20) -> 0 | H26: =COUNTIF(For_3060!$B$4:$B$33,'Análise Fornecedores'!H20) -> 0 | I26: =COUNTIF(For_3060!$B$4:$B$33,'Análise Fornecedores'!I20) -> 0 | J26: =COUNTIF(For_3060!$J$4:$J$33,"Sim") -> 0 | K26: ='A3060'!$B$7 -> 0.001130204 | L26: ='A3060'!$D$7 -> ENQUADRADO
D27: Sicoob Credijur | E27: 3233 | F27: {=IFERROR(SUMPRODUCT((FREQUENCY(IF(For_3233!D4:D33<>"",MATCH(For_3233!D4:D33,For_3233!D4:D33,0)),ROW(For_3233!D4:D33)-ROW(For_3233!D4)+1)>0)*1),0)} -> 0 | G27: =COUNTIF(For_3233!$B$4:$B$33,'Análise Fornecedores'!G20) -> 0 | H27: =COUNTIF(For_3233!$B$4:$B$33,'Análise Fornecedores'!H20) -> 0 | I27: =COUNTIF(For_3233!$B$4:$B$33,'Análise Fornecedores'!I20) -> 0 | J27: =COUNTIF(For_3233!$J$4:$J$33,"Sim") -> 0 | K27: ='A3233'!$B$7 -> 9.0400554e-05 | L27: ='A3233'!$D$7 -> ENQUADRADO
D28: Sicoob Credicapa | E28: 3261 | F28: {=IFERROR(SUMPRODUCT((FREQUENCY(IF(For_3261!D4:D33<>"",MATCH(For_3261!D4:D33,For_3261!D4:D33,0)),ROW(For_3261!D4:D33)-ROW(For_3261!D4)+1)>0)*1),0)} -> 0 | G28: =COUNTIF(For_3261!$B$4:$B$33,'Análise Fornecedores'!G20) -> 0 | H28: =COUNTIF(For_3261!$B$4:$B$33,'Análise Fornecedores'!H20) -> 0 | I28: =COUNTIF(For_3261!$B$4:$B$33,'Análise Fornecedores'!I20) -> 0 | J28: =COUNTIF(For_3261!$J$4:$J$33,"Sim") -> 0 | K28: ='A3261'!$B$7 -> 0.00021348374 | L28: ='A3261'!$D$7 -> ENQUADRADO
D29: Sicoob Tocantins | E29: 3263 | F29: {=IFERROR(SUMPRODUCT((FREQUENCY(IF(For_3263!D4:D33<>"",MATCH(For_3263!D4:D33,For_3263!D4:D33,0)),ROW(For_3263!D4:D33)-ROW(For_3263!D4)+1)>0)*1),0)} -> 0 | G29: =COUNTIF(For_3263!$B$4:$B$33,'Análise Fornecedores'!G20) -> 0 | H29: =COUNTIF(For_3263!$B$4:$B$33,'Análise Fornecedores'!H20) -> 0 | I29: =COUNTIF(For_3263!$B$4:$B$33,'Análise Fornecedores'!I20) -> 0 | J29: =COUNTIF(For_3263!$J$4:$J$33,"Sim") -> 0 | K29: ='A3263'!$B$7 -> 0.0027366321 | L29: ='A3263'!$D$7 -> ENQUADRADO
D30: Sicoob Cerrado | E30: 3320 | F30: {=IFERROR(SUMPRODUCT((FREQUENCY(IF(For_3320!D4:D33<>"",MATCH(For_3320!D4:D33,For_3320!D4:D33,0)),ROW(For_3320!D4:D33)-ROW(For_3320!D4)+1)>0)*1),0)} -> 0 | G30: =COUNTIF(For_3320!$B$4:$B$33,'Análise Fornecedores'!G20) -> 0 | H30: =COUNTIF(For_3320!$B$4:$B$33,'Análise Fornecedores'!H20) -> 0 | I30: =COUNTIF(For_3320!$B$4:$B$33,'Análise Fornecedores'!I20) -> 0 | J30: =COUNTIF(For_3320!$J$4:$J$33,"Sim") -> 0 | K30: ='A3320'!$B$7 -> 0.00016578276 | L30: ='A3320'!$D$7 -> ENQUADRADO
D31: Sicoob Emprecred | E31: 3332 | F31: {=IFERROR(SUMPRODUCT((FREQUENCY(IF(For_3332!D4:D33<>"",MATCH(For_3332!D4:D33,For_3332!D4:D33,0)),ROW(For_3332!D4:D33)-ROW(For_3332!D4)+1)>0)*1),0)} -> 0 | G31: =COUNTIF(For_3332!$B$4:$B$33,'Análise Fornecedores'!G20) -> 0 | H31: =COUNTIF(For_3332!$B$4:$B$33,'Análise Fornecedores'!H20) -> 0 | I31: =COUNTIF(For_3332!$B$4:$B$33,'Análise Fornecedores'!I20) -> 0 | J31: =COUNTIF(For_3332!$J$4:$J$33,"Sim") -> 0 | K31: ='A3332'!$B$7 -> 0.0042429209 | L31: ='A3332'!$D$7 -> ENQUADRADO
D32: Sicob Secovicred | E32: 3333 | F32: {=IFERROR(SUMPRODUCT((FREQUENCY(IF(For_3333!D4:D33<>"",MATCH(For_3333!D4:D33,For_3333!D4:D33,0)),ROW(For_3333!D4:D33)-ROW(For_3333!D4)+1)>0)*1),0)} -> 0 | G32: =COUNTIF(For_3333!$B$4:$B$33,'Análise Fornecedores'!G20) -> 0 | H32: =COUNTIF(For_3333!$B$4:$B$33,'Análise Fornecedores'!H20) -> 0 | I32: =COUNTIF(For_3333!$B$4:$B$33,'Análise Fornecedores'!I20) -> 0 | J32: =COUNTIF(For_3333!$J$4:$J$33,"Sim") -> 0 | K32: ='A3333'!$B$7 -> 0.00022086738 | L32: ='A3333'!$D$7 -> ENQUADRADO
D33: Sicoob Juriscredcelg | E33: 3348 | F33: {=IFERROR(SUMPRODUCT((FREQUENCY(IF(For_3348!D4:D33<>"",MATCH(For_3348!D4:D33,For_3348!D4:D33,0)),ROW(For_3348!D4:D33)-ROW(For_3348!D4)+1)>0)*1),0)} -> 0 | G33: =COUNTIF(For_3348!$B$4:$B$33,'Análise Fornecedores'!G20) -> 0 | H33: =COUNTIF(For_3348!$B$4:$B$33,'Análise Fornecedores'!H20) -> 0 | I33: =COUNTIF(For_3348!$B$4:$B$33,'Análise Fornecedores'!I20) -> 0 | J33: =COUNTIF(For_3348!$J$4:$J$33,"Sim") -> 0 | K33: ='A3348'!$B$7 -> 0.0021647808 | L33: ='A3348'!$D$7 -> ENQUADRADO
D34: Sicoob Credicer | E34: 3349 | F34: {=IFERROR(SUMPRODUCT((FREQUENCY(IF(For_3349!D4:D33<>"",MATCH(For_3349!D4:D33,For_3349!D4:D33,0)),ROW(For_3349!D4:D33)-ROW(For_3349!D4)+1)>0)*1),0)} -> 0 | G34: =COUNTIF(For_3349!$B$4:$B$33,'Análise Fornecedores'!G20) -> 0 | H34: =COUNTIF(For_3349!$B$4:$B$33,'Análise Fornecedores'!H20) -> 0 | I34: =COUNTIF(For_3349!$B$4:$B$33,'Análise Fornecedores'!I20) -> 0 | J34: =COUNTIF(For_3349!$J$4:$J$33,"Sim") -> 0 | K34: ='A3349'!$B$7 -> 0.00050162307 | L34: ='A3349'!$D$7 -> ENQUADRADO
D35: Sicoob Crediadag | E35: 3351 | F35: {=IFERROR(SUMPRODUCT((FREQUENCY(IF(For_3351!D4:D33<>"",MATCH(For_3351!D4:D33,For_3351!D4:D33,0)),ROW(For_3351!D4:D33)-ROW(For_3351!D4)+1)>0)*1),0)} -> 0 | G35: =COUNTIF(For_3351!$B$4:$B$33,'Análise Fornecedores'!G20) -> 0 | H35: =COUNTIF(For_3351!$B$4:$B$33,'Análise Fornecedores'!H20) -> 0 | I35: =COUNTIF(For_3351!$B$4:$B$33,'Análise Fornecedores'!I20) -> 0 | J35: =COUNTIF(For_3351!$J$4:$J$33,"Sim") -> 0 | K35: ='A3351'!$B$7 -> 0.00017615884 | L35: ='A3351'!$D$7 -> ENQUADRADO
D36: Sicoob Empresarial | E36: 3343 | F36: {=IFERROR(SUMPRODUCT((FREQUENCY(IF(For_3343!D5:D34<>"",MATCH(For_3343!D5:D34,For_3343!D5:D34,0)),ROW(For_3343!D5:D34)-ROW(For_3343!D5)+1)>0)*1),0)} -> 0 | G36: =COUNTIF(For_3343!$B$4:$B$33,'Análise Fornecedores'!G21) -> 0 | H36: =COUNTIF(For_3343!$B$4:$B$33,'Análise Fornecedores'!H21) -> 0 | I36: =COUNTIF(For_3343!$B$4:$B$33,'Análise Fornecedores'!I21) -> 0 | J36: =COUNTIF(For_3343!$J$4:$J$33,"Sim") -> 0 | K36: ='A3343'!$B$7 -> 0.00059554088 | L36: ='A3343'!$D$7 -> ENQUADRADO
D37: Sicoob Cooprem | E37: 3350 | F37: {=IFERROR(SUMPRODUCT((FREQUENCY(IF(For_3350!D6:D35<>"",MATCH(For_3350!D6:D35,For_3350!D6:D35,0)),ROW(For_3350!D6:D35)-ROW(For_3350!D6)+1)>0)*1),0)} -> 0 | G37: =COUNTIF(For_3350!$B$4:$B$33,'Análise Fornecedores'!G22) -> 0 | H37: =COUNTIF(For_3350!$B$4:$B$33,'Análise Fornecedores'!H22) -> 0 | I37: =COUNTIF(For_3350!$B$4:$B$33,'Análise Fornecedores'!I22) -> 0 | J37: =COUNTIF(For_3350!$J$4:$J$33,"Sim") -> 0 | K37: ='A3350'!$B$7 -> 0.0007974932 | L37: ='A3350'!$D$7 -> ENQUADRADO
D38: Sicoob Credi-Comigo | E38: 3336 | F38: {=IFERROR(SUMPRODUCT((FREQUENCY(IF(For_3336!D7:D36<>"",MATCH(For_3336!D7:D36,For_3336!D7:D36,0)),ROW(For_3336!D7:D36)-ROW(For_3336!D7)+1)>0)*1),0)} -> 0 | G38: =COUNTIF(For_3336!$B$4:$B$33,'Análise Fornecedores'!G23) -> 0 | H38: =COUNTIF(For_3336!$B$4:$B$33,'Análise Fornecedores'!H23) -> 0 | I38: =COUNTIF(For_3336!$B$4:$B$33,'Análise Fornecedores'!I23) -> 0 | J38: =COUNTIF(For_3336!$J$4:$J$33,"Sim") -> 0 | K38: ='A3336'!$B$7 -> 0.0037773558 | L38: ='A3336'!$D$7 -> ENQUADRADO
D39: Sicoob Credigóias | E39: 3058 | F39: {=IFERROR(SUMPRODUCT((FREQUENCY(IF(For_3058!D8:D37<>"",MATCH(For_3058!D8:D37,For_3058!D8:D37,0)),ROW(For_3058!D8:D37)-ROW(For_3058!D8)+1)>0)*1),0)} -> 0 | G39: =COUNTIF(For_3058!$B$4:$B$33,'Análise Fornecedores'!G24) -> 0 | H39: =COUNTIF(For_3058!$B$4:$B$33,'Análise Fornecedores'!H24) -> 0 | I39: =COUNTIF(For_3058!$B$4:$B$33,'Análise Fornecedores'!I24) -> 0 | J39: =COUNTIF(For_3058!$J$4:$J$33,"Sim") -> 0 | K39: ='A3058'!$B$7 -> 0 | L39: ='A3058'!$D$7 -> ENQUADRADO
D40: Sicoob Coopercred | E40: 3055 | F40: {=IFERROR(SUMPRODUCT((FREQUENCY(IF(For_3055!D9:D38<>"",MATCH(For_3055!D9:D38,For_3055!D9:D38,0)),ROW(For_3055!D9:D38)-ROW(For_3055!D9)+1)>0)*1),0)} -> 0 | G40: =COUNTIF(For_3055!$B$4:$B$33,'Análise Fornecedores'!G25) -> 0 | H40: =COUNTIF(For_3055!$B$4:$B$33,'Análise Fornecedores'!H25) -> 0 | I40: =COUNTIF(For_3055!$B$4:$B$33,'Análise Fornecedores'!I25) -> 0 | J40: =COUNTIF(For_3055!$J$4:$J$33,"Sim") -> 0 | K40: ='A3055'!$B$7 -> 2.5282051e-05 | L40: ='A3055'!$D$7 -> ENQUADRADO
D41: Sicoob Unicidades | E41: 5014 | F41: {=IFERROR(SUMPRODUCT((FREQUENCY(IF(For_5014!D10:D39<>"",MATCH(For_5014!D10:D39,For_5014!D10:D39,0)),ROW(For_5014!D10:D39)-ROW(For_5014!D10)+1)>0)*1),0)} -> 0 | G41: =COUNTIF(For_5014!$B$4:$B$33,'Análise Fornecedores'!G26) -> 0 | H41: =COUNTIF(For_5014!$B$4:$B$33,'Análise Fornecedores'!H26) -> 0 | I41: =COUNTIF(For_5014!$B$4:$B$33,'Análise Fornecedores'!I26) -> 0 | J41: =COUNTIF(For_5014!$J$4:$J$33,"Sim") -> 0 | K41: ='A5014'!$B$7 -> 0.0012800826 | L41: ='A5014'!$D$7 -> ENQUADRADO
D42: Sicoob Mineiros | E42: 3056 | F42: {=IFERROR(SUMPRODUCT((FREQUENCY(IF(For_3056!D11:D40<>"",MATCH(For_3056!D11:D40,For_3056!D11:D40,0)),ROW(For_3056!D11:D40)-ROW(For_3056!D11)+1)>0)*1),0)} -> 0 | G42: =COUNTIF(For_3056!$B$4:$B$33,'Análise Fornecedores'!G27) -> 0 | H42: =COUNTIF(For_3056!$B$4:$B$33,'Análise Fornecedores'!H27) -> 0 | I42: =COUNTIF(For_3056!$B$4:$B$33,'Análise Fornecedores'!I27) -> 0 | J42: =COUNTIF(For_3056!$J$4:$J$33,"Sim") -> 0 | K42: ='A3056'!$B$7 -> 0.00019725333 | L42: ='A3056'!$D$7 -> ENQUADRADO
D43: Sicoob Centro Oeste BR | E43: 3300 | F43: {=IFERROR(SUMPRODUCT((FREQUENCY(IF(For_3300!D12:D41<>"",MATCH(For_3300!D12:D41,For_3300!D12:D41,0)),ROW(For_3300!D12:D41)-ROW(For_3300!D12)+1)>0)*1),0)} -> 0 | G43: =COUNTIF(For_3300!$B$4:$B$33,'Análise Fornecedores'!G28) -> 0 | H43: =COUNTIF(For_3300!$B$4:$B$33,'Análise Fornecedores'!H28) -> 0 | I43: =COUNTIF(For_3300!$B$4:$B$33,'Análise Fornecedores'!I28) -> 0 | J43: =COUNTIF(For_3300!$J$4:$J$33,"Sim") -> 0 | K43: ='A3300'!$B$7 -> 0.0014007534 | L43: ='A3300'!$D$7 -> ENQUADRADO
D44: Sicoob Executivo | E44: 4001 | F44: {=IFERROR(SUMPRODUCT((FREQUENCY(IF(For_4001!D4:D33<>"",MATCH(For_4001!D4:D33,For_4001!D4:D33,0)),ROW(For_4001!D4:D33)-ROW(For_4001!D4)+1)>0)*1),0)} -> 0 | G44: =COUNTIF(For_4001!$B$4:$B$33,'Análise Fornecedores'!G20) -> 0 | H44: =COUNTIF(For_4001!$B$4:$B$33,'Análise Fornecedores'!H20) -> 0 | I44: =COUNTIF(For_4001!$B$4:$B$33,'Análise Fornecedores'!I20) -> 0 | J44: =COUNTIF(For_4001!$J$4:$J$33,"Sim") -> 0 | K44: ='A4001'!$B$7 -> 0.0035291857 | L44: ='A4001'!$D$7 -> ENQUADRADO
D45: Sicoob Judiciário | E45: 4002 | F45: {=IFERROR(SUMPRODUCT((FREQUENCY(IF(For_4002!D4:D33<>"",MATCH(For_4002!D4:D33,For_4002!D4:D33,0)),ROW(For_4002!D4:D33)-ROW(For_4002!D4)+1)>0)*1),0)} -> 0 | G45: =COUNTIF(For_4002!$B$4:$B$33,'Análise Fornecedores'!G20) -> 0 | H45: =COUNTIF(For_4002!$B$4:$B$33,'Análise Fornecedores'!H20) -> 0 | I45: =COUNTIF(For_4002!$B$4:$B$33,'Análise Fornecedores'!I20) -> 0 | J45: =COUNTIF(For_4002!$J$4:$J$33,"Sim") -> 0 | K45: ='A4002'!$B$7 -> 0.0076650377 | L45: ='A4002'!$D$7 -> ENQUADRADO
D46: Sicoob Credijustra | E46: 4041 | F46: {=IFERROR(SUMPRODUCT((FREQUENCY(IF(For_4041!D4:D33<>"",MATCH(For_4041!D4:D33,For_4041!D4:D33,0)),ROW(For_4041!D4:D33)-ROW(For_4041!D4)+1)>0)*1),0)} -> 0 | G46: =COUNTIF(For_4041!$B$4:$B$33,'Análise Fornecedores'!G20) -> 0 | H46: =COUNTIF(For_4041!$B$4:$B$33,'Análise Fornecedores'!H20) -> 0 | I46: =COUNTIF(For_4041!$B$4:$B$33,'Análise Fornecedores'!I20) -> 0 | J46: =COUNTIF(For_4041!$J$4:$J$33,"Sim") -> 0 | K46: ='A4041'!$B$7 -> 0.00062994522 | L46: ='A4041'!$D$7 -> ENQUADRADO
D47: Sicoob Credibrasília | E47: 4155 | F47: {=IFERROR(SUMPRODUCT((FREQUENCY(IF(For_4155!D4:D33<>"",MATCH(For_4155!D4:D33,For_4155!D4:D33,0)),ROW(For_4155!D4:D33)-ROW(For_4155!D4)+1)>0)*1),0)} -> 0 | G47: =COUNTIF(For_4155!$B$4:$B$33,'Análise Fornecedores'!G20) -> 0 | H47: =COUNTIF(For_4155!$B$4:$B$33,'Análise Fornecedores'!H20) -> 0 | I47: =COUNTIF(For_4155!$B$4:$B$33,'Análise Fornecedores'!I20) -> 0 | J47: =COUNTIF(For_4155!$J$4:$J$33,"Sim") -> 0 | K47: ='A4155'!$B$7 -> 9.5332976e-05 | L47: ='A4155'!$D$7 -> ENQUADRADO
D48: Sicoob Crediembrapa | E48: 4198 | F48: {=IFERROR(SUMPRODUCT((FREQUENCY(IF(For_4198!D4:D33<>"",MATCH(For_4198!D4:D33,For_4198!D4:D33,0)),ROW(For_4198!D4:D33)-ROW(For_4198!D4)+1)>0)*1),0)} -> 0 | G48: =COUNTIF(For_4198!$B$4:$B$33,'Análise Fornecedores'!G20) -> 0 | H48: =COUNTIF(For_4198!$B$4:$B$33,'Análise Fornecedores'!H20) -> 0 | I48: =COUNTIF(For_4198!$B$4:$B$33,'Análise Fornecedores'!I20) -> 0 | J48: =COUNTIF(For_4198!$J$4:$J$33,"Sim") -> 0 | K48: ='A4198'!$B$7 -> 0.00096319199 | L48: ='A4198'!$D$7 -> ENQUADRADO
D49: Sicoob Credfaz | E49: 4221 | F49: {=IFERROR(SUMPRODUCT((FREQUENCY(IF(For_4221!D4:D33<>"",MATCH(For_4221!D4:D33,For_4221!D4:D33,0)),ROW(For_4221!D4:D33)-ROW(For_4221!D4)+1)>0)*1),0)} -> 0 | G49: =COUNTIF(For_4221!$B$4:$B$33,'Análise Fornecedores'!G20) -> 0 | H49: =COUNTIF(For_4221!$B$4:$B$33,'Análise Fornecedores'!H20) -> 0 | I49: =COUNTIF(For_4221!$B$4:$B$33,'Análise Fornecedores'!I20) -> 0 | J49: =COUNTIF(For_4221!$J$4:$J$33,"Sim") -> 0 | K49: ='A4221'!$B$7 -> 4.2772302e-05 | L49: ='A4221'!$D$7 -> ENQUADRADO
D50: Sicoob Cooperplan Credsef | E50: 4278 | F50: {=IFERROR(SUMPRODUCT((FREQUENCY(IF(For_4278!D4:D33<>"",MATCH(For_4278!D4:D33,For_4278!D4:D33,0)),ROW(For_4278!D4:D33)-ROW(For_4278!D4)+1)>0)*1),0)} -> 0 | G50: =COUNTIF(For_4278!$B$4:$B$33,'Análise Fornecedores'!G20) -> 0 | H50: =COUNTIF(For_4278!$B$4:$B$33,'Análise Fornecedores'!H20) -> 0 | I50: =COUNTIF(For_4278!$B$4:$B$33,'Análise Fornecedores'!I20) -> 0 | J50: =COUNTIF(For_4278!$J$4:$J$33,"Sim") -> 0 | K50: ='A4278'!$B$7 -> 0 | L50: ='A4278'!$D$7 -> ENQUADRADO
...

Sheet Cooperados Alto Risco
F4: PAPEL DE TRABALHO RSAC (Risco Social Ambiental e Climático) | O4: Retorno
C9: Elaborado por: Gleibson Carreiro de Sousa | F9: Data Base: | G9: 46023 | H9: Periodicadade: Mensal
C10: Revisado por: | F10: Data da Revisão
C13: RESULTADO
D15: ANÁLISE 05: Relatório de Alto Risco por Cooperativa - Quantitativo | S15: Quantidade de Planos de Ações PENDENTES de Cadastro
T16: =_xlfn.XLOOKUP(S18,D20:D51,I20:I51," ",0) -> 5
D17: CCONTROLE DOS PLANOS DE AÇÕES | F17: PGPC | S17: Escolha a cooperativa
F18: =EOMONTH(G9,-1)+1 -> 46023 | G18: a | H18: =EOMONTH(G9,0) -> 46053 | N18: Possibilidades | S18: TODAS as singulares | T18: Sicoob Agrorural | U18: Sicoob Centro-Sul | V18: Sicoob Credi-Rural | W18: Siccob do Vale | X18: Sicoob Palmeiras | Y18: Sicoob Credijur | Z18: Sicoob Credicapa | AA18: Sicoob Tocantins | AB18: Sicoob Cerrado | AC18: Sicoob Emprecred | AD18: Sicob Secovicred | AE18: Sicoob Juriscredcelg | AF18: Sicoob Credicer | AG18: Sicoob Crediadag | AH18: Sicoob Executivo | AI18: Sicoob Judiciário | AJ18: Sicoob Credijustra | AK18: Sicoob Credibrasília | AL18: Sicoob Crediembrapa | AM18: Sicoob Credfaz | AN18: Sicoob Cooperplan Credsef | AO18: Sicoob Dfmil | AP18: Sicoob Empresarial | AQ18: TODAS as singulares
D19: COOEPRATIVA | E19: AGÊNCIA | F19: ALTO RISCO | G19: % de planos de ações cadastrados na PGPC | H19: Quant. Planos Cadastrados | I19: Quant. de PLANOS PENDENTES DE CADASTRO | N19: Possíveis Causas do Plano de ação | T19: 3042 | U19: 3043 | V19: 3054 | W19: 3059 | X19: 3060 | Y19: 3233 | Z19: 3261 | AA19: 3263 | AB19: 3320 | AC19: 3332 | AD19: 3333 | AE19: 3348 | AF19: 3349 | AG19: 3351 | AH19: 4001 | AI19: 4002 | AJ19: 4041 | AK19: 4155 | AL19: 4198 | AM19: 4221 | AN19: 4278 | AO19: 4332 | AP19: 4364
D20: Sicoob Agrorural | E20: 3042 | F20: ='Risco por Cooperativa'!H21 -> 1 | G20: =IFERROR((COUNTIF('A3042'!$AL:$AL,"Sim"))/F20,0) -> 1 | H20: =COUNTIF('A3042'!$AL:$AL,"Sim") -> 1 | I20: =COUNTIF('A3042'!AM:AM,"Verificar") -> 0 | N20: Embargo | S20: =HLOOKUP($S$18,$T$18:$AQ$28,3,0) -> 0 | T20: =COUNTIFS('A3042'!$AK:$AK,'Cooperados Alto Risco'!N20) -> 0 | U20: =COUNTIFS('A3043'!$AK:$AK,'Cooperados Alto Risco'!N20) -> 0 | V20: =COUNTIFS('A3054'!$AK:$AK,'Cooperados Alto Risco'!N20) -> 0 | W20: =COUNTIFS('A3059'!$AK:$AK,'Cooperados Alto Risco'!N20) -> 0 | X20: =COUNTIFS('A3060'!$AK:$AK,'Cooperados Alto Risco'!N20) -> 0 | Y20: =COUNTIFS('A3233'!$AK:$AK,'Cooperados Alto Risco'!N20) -> 0 | Z20: =COUNTIFS('A3261'!$AK:$AK,'Cooperados Alto Risco'!N20) -> 0 | AA20: =COUNTIFS('A3263'!$AK:$AK,'Cooperados Alto Risco'!N20) -> 0 | AB20: =COUNTIFS('A3320'!$AK:$AK,'Cooperados Alto Risco'!N20) -> 0 | AC20: =COUNTIFS('A3332'!$AK:$AK,'Cooperados Alto Risco'!N20) -> 0 | AD20: =COUNTIFS('A3333'!$AK:$AK,'Cooperados Alto Risco'!N20) -> 0 | AE20: =COUNTIFS('A3348'!$AK:$AK,'Cooperados Alto Risco'!N20) -> 0 | AF20: =COUNTIFS('A3349'!$AK:$AK,'Cooperados Alto Risco'!N20) -> 0 | AG20: =COUNTIFS('A3351'!$AK:$AK,'Cooperados Alto Risco'!N20) -> 0 | AH20: =COUNTIFS('A4001'!$AK:$AK,'Cooperados Alto Risco'!N20) -> 0 | AI20: =COUNTIFS('A4002'!$AK:$AK,'Cooperados Alto Risco'!N20) -> 0 | AJ20: =COUNTIFS('A4041'!$AK:$AK,'Cooperados Alto Risco'!N20) -> 0 | AK20: =COUNTIFS('A4155'!$AK:$AK,'Cooperados Alto Risco'!N20) -> 0 | AL20: =COUNTIFS('A4198'!$AK:$AK,'Cooperados Alto Risco'!N20) -> 0 | AM20: =COUNTIFS('A4221'!$AK:$AK,'Cooperados Alto Risco'!N20) -> 0 | AN20: =COUNTIFS('A4278'!$AK:$AK,'Cooperados Alto Risco'!N20) -> 0 | AO20: =COUNTIFS('A4332'!$AK:$AK,'Cooperados Alto Risco'!N20) -> 0 | AP20: =COUNTIFS('A4364'!$AK:$AK,'Cooperados Alto Risco'!N20) -> 0 | AQ20: =SUM(T20:AP20) -> 0
D21: Sicoob Centro-Sul | E21: 3043 | F21: ='Risco por Cooperativa'!H22 -> 2 | G21: =IFERROR((COUNTIF('A3043'!$AL:$AL,"Sim"))/F21,0) -> 1 | H21: =COUNTIF('A3043'!$AL:$AL,"Sim") -> 2 | I21: =COUNTIF('A3043'!AM:AM,"Verificar") -> 0 | N21: Contraparte Conectada | S21: =HLOOKUP($S$18,$T$18:$AQ$28,4,0) -> 0 | T21: =COUNTIFS('A3042'!$AK:$AK,'Cooperados Alto Risco'!N21) -> 0 | U21: =COUNTIFS('A3043'!$AK:$AK,'Cooperados Alto Risco'!N21) -> 0 | V21: =COUNTIFS('A3054'!$AK:$AK,'Cooperados Alto Risco'!N21) -> 0 | W21: =COUNTIFS('A3059'!$AK:$AK,'Cooperados Alto Risco'!N21) -> 0 | X21: =COUNTIFS('A3060'!$AK:$AK,'Cooperados Alto Risco'!N21) -> 0 | Y21: =COUNTIFS('A3233'!$AK:$AK,'Cooperados Alto Risco'!N21) -> 0 | Z21: =COUNTIFS('A3261'!$AK:$AK,'Cooperados Alto Risco'!N21) -> 0 | AA21: =COUNTIFS('A3263'!$AK:$AK,'Cooperados Alto Risco'!N21) -> 0 | AB21: =COUNTIFS('A3320'!$AK:$AK,'Cooperados Alto Risco'!N21) -> 0 | AC21: =COUNTIFS('A3332'!$AK:$AK,'Cooperados Alto Risco'!N21) -> 0 | AD21: =COUNTIFS('A3333'!$AK:$AK,'Cooperados Alto Risco'!N21) -> 0 | AE21: =COUNTIFS('A3348'!$AK:$AK,'Cooperados Alto Risco'!N21) -> 0 | AF21: =COUNTIFS('A3349'!$AK:$AK,'Cooperados Alto Risco'!N21) -> 0 | AG21: =COUNTIFS('A3351'!$AK:$AK,'Cooperados Alto Risco'!N21) -> 0 | AH21: =COUNTIFS('A4001'!$AK:$AK,'Cooperados Alto Risco'!N21) -> 0 | AI21: =COUNTIFS('A4002'!$AK:$AK,'Cooperados Alto Risco'!N21) -> 0 | AJ21: =COUNTIFS('A4041'!$AK:$AK,'Cooperados Alto Risco'!N21) -> 0 | AK21: =COUNTIFS('A4155'!$AK:$AK,'Cooperados Alto Risco'!N21) -> 0 | AL21: =COUNTIFS('A4198'!$AK:$AK,'Cooperados Alto Risco'!N21) -> 0 | AM21: =COUNTIFS('A4221'!$AK:$AK,'Cooperados Alto Risco'!N21) -> 0 | AN21: =COUNTIFS('A4278'!$AK:$AK,'Cooperados Alto Risco'!N21) -> 0 | AO21: =COUNTIFS('A4332'!$AK:$AK,'Cooperados Alto Risco'!N21) -> 0 | AP21: =COUNTIFS('A4364'!$AK:$AK,'Cooperados Alto Risco'!N21) -> 0 | AQ21: =SUM(T21:AP21) -> 0
D22: Sicoob Credi-Rural | E22: 3054 | F22: ='Risco por Cooperativa'!H23 -> 9 | G22: =IFERROR((COUNTIF('A3054'!$AL:$AL,"Sim"))/F22,0) -> 0.88888889 | H22: =COUNTIF('A3054'!$AL:$AL,"Sim") -> 8 | I22: =COUNTIF('A3054'!AM:AM,"Verificar") -> 1 | N22: Licenciamento Ambiental | S22: =HLOOKUP($S$18,$T$18:$AQ$28,5,0) -> 0 | T22: =COUNTIFS('A3042'!$AK:$AK,'Cooperados Alto Risco'!N22) -> 0 | U22: =COUNTIFS('A3043'!$AK:$AK,'Cooperados Alto Risco'!N22) -> 0 | V22: =COUNTIFS('A3054'!$AK:$AK,'Cooperados Alto Risco'!N22) -> 0 | W22: =COUNTIFS('A3059'!$AK:$AK,'Cooperados Alto Risco'!N22) -> 0 | X22: =COUNTIFS('A3060'!$AK:$AK,'Cooperados Alto Risco'!N22) -> 0 | Y22: =COUNTIFS('A3233'!$AK:$AK,'Cooperados Alto Risco'!N22) -> 0 | Z22: =COUNTIFS('A3261'!$AK:$AK,'Cooperados Alto Risco'!N22) -> 0 | AA22: =COUNTIFS('A3263'!$AK:$AK,'Cooperados Alto Risco'!N22) -> 0 | AB22: =COUNTIFS('A3320'!$AK:$AK,'Cooperados Alto Risco'!N22) -> 0 | AC22: =COUNTIFS('A3332'!$AK:$AK,'Cooperados Alto Risco'!N22) -> 0 | AD22: =COUNTIFS('A3333'!$AK:$AK,'Cooperados Alto Risco'!N22) -> 0 | AE22: =COUNTIFS('A3348'!$AK:$AK,'Cooperados Alto Risco'!N22) -> 0 | AF22: =COUNTIFS('A3349'!$AK:$AK,'Cooperados Alto Risco'!N22) -> 0 | AG22: =COUNTIFS('A3351'!$AK:$AK,'Cooperados Alto Risco'!N22) -> 0 | AH22: =COUNTIFS('A4001'!$AK:$AK,'Cooperados Alto Risco'!N22) -> 0 | AI22: =COUNTIFS('A4002'!$AK:$AK,'Cooperados Alto Risco'!N22) -> 0 | AJ22: =COUNTIFS('A4041'!$AK:$AK,'Cooperados Alto Risco'!N22) -> 0 | AK22: =COUNTIFS('A4155'!$AK:$AK,'Cooperados Alto Risco'!N22) -> 0 | AL22: =COUNTIFS('A4198'!$AK:$AK,'Cooperados Alto Risco'!N22) -> 0 | AM22: =COUNTIFS('A4221'!$AK:$AK,'Cooperados Alto Risco'!N22) -> 0 | AN22: =COUNTIFS('A4278'!$AK:$AK,'Cooperados Alto Risco'!N22) -> 0 | AO22: =COUNTIFS('A4332'!$AK:$AK,'Cooperados Alto Risco'!N22) -> 0 | AP22: =COUNTIFS('A4364'!$AK:$AK,'Cooperados Alto Risco'!N22) -> 0 | AQ22: =SUM(T22:AP22) -> 0
D23: Siccob do Vale | E23: 3059 | F23: ='Risco por Cooperativa'!H24 -> 1 | G23: =IFERROR((COUNTIF('A3059'!$AL:$AL,"Sim"))/F23,0) -> 1 | H23: =COUNTIF('A3059'!$AL:$AL,"Sim") -> 1 | I23: =COUNTIF('A3059'!AM:AM,"Verificar") -> 0 | N23: Trabalho Escravo | S23: =HLOOKUP($S$18,$T$18:$AQ$28,6,0) -> 0 | T23: =COUNTIFS('A3042'!$AK:$AK,'Cooperados Alto Risco'!N23) -> 0 | U23: =COUNTIFS('A3043'!$AK:$AK,'Cooperados Alto Risco'!N23) -> 0 | V23: =COUNTIFS('A3054'!$AK:$AK,'Cooperados Alto Risco'!N23) -> 0 | W23: =COUNTIFS('A3059'!$AK:$AK,'Cooperados Alto Risco'!N23) -> 0 | X23: =COUNTIFS('A3060'!$AK:$AK,'Cooperados Alto Risco'!N23) -> 0 | Y23: =COUNTIFS('A3233'!$AK:$AK,'Cooperados Alto Risco'!N23) -> 0 | Z23: =COUNTIFS('A3261'!$AK:$AK,'Cooperados Alto Risco'!N23) -> 0 | AA23: =COUNTIFS('A3263'!$AK:$AK,'Cooperados Alto Risco'!N23) -> 0 | AB23: =COUNTIFS('A3320'!$AK:$AK,'Cooperados Alto Risco'!N23) -> 0 | AC23: =COUNTIFS('A3332'!$AK:$AK,'Cooperados Alto Risco'!N23) -> 0 | AD23: =COUNTIFS('A3333'!$AK:$AK,'Cooperados Alto Risco'!N23) -> 0 | AE23: =COUNTIFS('A3348'!$AK:$AK,'Cooperados Alto Risco'!N23) -> 0 | AF23: =COUNTIFS('A3349'!$AK:$AK,'Cooperados Alto Risco'!N23) -> 0 | AG23: =COUNTIFS('A3351'!$AK:$AK,'Cooperados Alto Risco'!N23) -> 0 | AH23: =COUNTIFS('A4001'!$AK:$AK,'Cooperados Alto Risco'!N23) -> 0 | AI23: =COUNTIFS('A4002'!$AK:$AK,'Cooperados Alto Risco'!N23) -> 0 | AJ23: =COUNTIFS('A4041'!$AK:$AK,'Cooperados Alto Risco'!N23) -> 0 | AK23: =COUNTIFS('A4155'!$AK:$AK,'Cooperados Alto Risco'!N23) -> 0 | AL23: =COUNTIFS('A4198'!$AK:$AK,'Cooperados Alto Risco'!N23) -> 0 | AM23: =COUNTIFS('A4221'!$AK:$AK,'Cooperados Alto Risco'!N23) -> 0 | AN23: =COUNTIFS('A4278'!$AK:$AK,'Cooperados Alto Risco'!N23) -> 0 | AO23: =COUNTIFS('A4332'!$AK:$AK,'Cooperados Alto Risco'!N23) -> 0 | AP23: =COUNTIFS('A4364'!$AK:$AK,'Cooperados Alto Risco'!N23) -> 0 | AQ23: =SUM(T23:AP23) -> 0
D24: Sicoob Palmeiras | E24: 3060 | F24: ='Risco por Cooperativa'!H25 -> 1 | G24: =IFERROR((COUNTIF('A3060'!$AL:$AL,"Sim"))/F24,0) -> 1 | H24: =COUNTIF('A3060'!$AL:$AL,"Sim") -> 1 | I24: =COUNTIF('A3060'!AM:AM,"Verificar") -> 0 | S24: =HLOOKUP($S$18,$T$18:$AQ$28,7,0) -> 0 | T24: =COUNTIFS('A3042'!$AK:$AK,'Cooperados Alto Risco'!N24) -> 0 | U24: =COUNTIFS('A3043'!$AK:$AK,'Cooperados Alto Risco'!N24) -> 0 | V24: =COUNTIFS('A3054'!$AK:$AK,'Cooperados Alto Risco'!N24) -> 0 | W24: =COUNTIFS('A3059'!$AK:$AK,'Cooperados Alto Risco'!N24) -> 0 | X24: =COUNTIFS('A3060'!$AK:$AK,'Cooperados Alto Risco'!N24) -> 0 | Y24: =COUNTIFS('A3233'!$AK:$AK,'Cooperados Alto Risco'!N24) -> 0 | Z24: =COUNTIFS('A3261'!$AK:$AK,'Cooperados Alto Risco'!N24) -> 0 | AA24: =COUNTIFS('A3263'!$AK:$AK,'Cooperados Alto Risco'!N24) -> 0 | AB24: =COUNTIFS('A3320'!$AK:$AK,'Cooperados Alto Risco'!N24) -> 0 | AC24: =COUNTIFS('A3332'!$AK:$AK,'Cooperados Alto Risco'!N24) -> 0 | AD24: =COUNTIFS('A3333'!$AK:$AK,'Cooperados Alto Risco'!N24) -> 0 | AE24: =COUNTIFS('A3348'!$AK:$AK,'Cooperados Alto Risco'!N24) -> 0 | AF24: =COUNTIFS('A3349'!$AK:$AK,'Cooperados Alto Risco'!N24) -> 0 | AG24: =COUNTIFS('A3351'!$AK:$AK,'Cooperados Alto Risco'!N24) -> 0 | AH24: =COUNTIFS('A4001'!$AK:$AK,'Cooperados Alto Risco'!N24) -> 0 | AI24: =COUNTIFS('A4002'!$AK:$AK,'Cooperados Alto Risco'!N24) -> 0 | AJ24: =COUNTIFS('A4041'!$AK:$AK,'Cooperados Alto Risco'!N24) -> 0 | AK24: =COUNTIFS('A4155'!$AK:$AK,'Cooperados Alto Risco'!N24) -> 0 | AL24: =COUNTIFS('A4198'!$AK:$AK,'Cooperados Alto Risco'!N24) -> 0 | AM24: =COUNTIFS('A4221'!$AK:$AK,'Cooperados Alto Risco'!N24) -> 0 | AN24: =COUNTIFS('A4278'!$AK:$AK,'Cooperados Alto Risco'!N24) -> 0 | AO24: =COUNTIFS('A4332'!$AK:$AK,'Cooperados Alto Risco'!N24) -> 0 | AP24: =COUNTIFS('A4364'!$AK:$AK,'Cooperados Alto Risco'!N24) -> 0 | AQ24: =SUM(T24:AP24) -> 0
D25: Sicoob Credijur | E25: 3233 | F25: ='Risco por Cooperativa'!H26 -> 0 | G25: =IFERROR((COUNTIF('A3233'!$AL:$AL,"Sim"))/F25,0) -> 0 | H25: =COUNTIF('A3233'!$AL:$AL,"Sim") -> 0 | I25: =COUNTIF('A3233'!AM:AM,"Verificar") -> 0 | S25: =HLOOKUP($S$18,$T$18:$AQ$28,8,0) -> 0 | T25: =COUNTIFS('A3042'!$AK:$AK,'Cooperados Alto Risco'!N25) -> 0 | U25: =COUNTIFS('A3043'!$AK:$AK,'Cooperados Alto Risco'!N25) -> 0 | V25: =COUNTIFS('A3054'!$AK:$AK,'Cooperados Alto Risco'!N25) -> 0 | W25: =COUNTIFS('A3059'!$AK:$AK,'Cooperados Alto Risco'!N25) -> 0 | X25: =COUNTIFS('A3060'!$AK:$AK,'Cooperados Alto Risco'!N25) -> 0 | Y25: =COUNTIFS('A3233'!$AK:$AK,'Cooperados Alto Risco'!N25) -> 0 | Z25: =COUNTIFS('A3261'!$AK:$AK,'Cooperados Alto Risco'!N25) -> 0 | AA25: =COUNTIFS('A3263'!$AK:$AK,'Cooperados Alto Risco'!N25) -> 0 | AB25: =COUNTIFS('A3320'!$AK:$AK,'Cooperados Alto Risco'!N25) -> 0 | AC25: =COUNTIFS('A3332'!$AK:$AK,'Cooperados Alto Risco'!N25) -> 0 | AD25: =COUNTIFS('A3333'!$AK:$AK,'Cooperados Alto Risco'!N25) -> 0 | AE25: =COUNTIFS('A3348'!$AK:$AK,'Cooperados Alto Risco'!N25) -> 0 | AF25: =COUNTIFS('A3349'!$AK:$AK,'Cooperados Alto Risco'!N25) -> 0 | AG25: =COUNTIFS('A3351'!$AK:$AK,'Cooperados Alto Risco'!N25) -> 0 | AH25: =COUNTIFS('A4001'!$AK:$AK,'Cooperados Alto Risco'!N25) -> 0 | AI25: =COUNTIFS('A4002'!$AK:$AK,'Cooperados Alto Risco'!N25) -> 0 | AJ25: =COUNTIFS('A4041'!$AK:$AK,'Cooperados Alto Risco'!N25) -> 0 | AK25: =COUNTIFS('A4155'!$AK:$AK,'Cooperados Alto Risco'!N25) -> 0 | AL25: =COUNTIFS('A4198'!$AK:$AK,'Cooperados Alto Risco'!N25) -> 0 | AM25: =COUNTIFS('A4221'!$AK:$AK,'Cooperados Alto Risco'!N25) -> 0 | AN25: =COUNTIFS('A4278'!$AK:$AK,'Cooperados Alto Risco'!N25) -> 0 | AO25: =COUNTIFS('A4332'!$AK:$AK,'Cooperados Alto Risco'!N25) -> 0 | AP25: =COUNTIFS('A4364'!$AK:$AK,'Cooperados Alto Risco'!N25) -> 0 | AQ25: =SUM(T25:AP25) -> 0
D26: Sicoob Credicapa | E26: 3261 | F26: ='Risco por Cooperativa'!H27 -> 1 | G26: =IFERROR((COUNTIF('A3261'!$AL:$AL,"Sim"))/F26,0) -> 1 | H26: =COUNTIF('A3261'!$AL:$AL,"Sim") -> 1 | I26: =COUNTIF('A3261'!AM:AM,"Verificar") -> 0 | S26: =HLOOKUP($S$18,$T$18:$AQ$28,9,0) -> 0 | T26: =COUNTIFS('A3042'!$AK:$AK,'Cooperados Alto Risco'!N26) -> 0 | U26: =COUNTIFS('A3043'!$AK:$AK,'Cooperados Alto Risco'!N26) -> 0 | V26: =COUNTIFS('A3054'!$AK:$AK,'Cooperados Alto Risco'!N26) -> 0 | W26: =COUNTIFS('A3059'!$AK:$AK,'Cooperados Alto Risco'!N26) -> 0 | X26: =COUNTIFS('A3060'!$AK:$AK,'Cooperados Alto Risco'!N26) -> 0 | Y26: =COUNTIFS('A3233'!$AK:$AK,'Cooperados Alto Risco'!N26) -> 0 | Z26: =COUNTIFS('A3261'!$AK:$AK,'Cooperados Alto Risco'!N26) -> 0 | AA26: =COUNTIFS('A3263'!$AK:$AK,'Cooperados Alto Risco'!N26) -> 0 | AB26: =COUNTIFS('A3320'!$AK:$AK,'Cooperados Alto Risco'!N26) -> 0 | AC26: =COUNTIFS('A3332'!$AK:$AK,'Cooperados Alto Risco'!N26) -> 0 | AD26: =COUNTIFS('A3333'!$AK:$AK,'Cooperados Alto Risco'!N26) -> 0 | AE26: =COUNTIFS('A3348'!$AK:$AK,'Cooperados Alto Risco'!N26) -> 0 | AF26: =COUNTIFS('A3349'!$AK:$AK,'Cooperados Alto Risco'!N26) -> 0 | AG26: =COUNTIFS('A3351'!$AK:$AK,'Cooperados Alto Risco'!N26) -> 0 | AH26: =COUNTIFS('A4001'!$AK:$AK,'Cooperados Alto Risco'!N26) -> 0 | AI26: =COUNTIFS('A4002'!$AK:$AK,'Cooperados Alto Risco'!N26) -> 0 | AJ26: =COUNTIFS('A4041'!$AK:$AK,'Cooperados Alto Risco'!N26) -> 0 | AK26: =COUNTIFS('A4155'!$AK:$AK,'Cooperados Alto Risco'!N26) -> 0 | AL26: =COUNTIFS('A4198'!$AK:$AK,'Cooperados Alto Risco'!N26) -> 0 | AM26: =COUNTIFS('A4221'!$AK:$AK,'Cooperados Alto Risco'!N26) -> 0 | AN26: =COUNTIFS('A4278'!$AK:$AK,'Cooperados Alto Risco'!N26) -> 0 | AO26: =COUNTIFS('A4332'!$AK:$AK,'Cooperados Alto Risco'!N26) -> 0 | AP26: =COUNTIFS('A4364'!$AK:$AK,'Cooperados Alto Risco'!N26) -> 0 | AQ26: =SUM(T26:AP26) -> 0
D27: Sicoob Tocantins | E27: 3263 | F27: ='Risco por Cooperativa'!H28 -> 2 | G27: =IFERROR((COUNTIF('A3263'!$AL:$AL,"Sim"))/F27,0) -> 0.5 | H27: =COUNTIF('A3263'!$AL:$AL,"Sim") -> 1 | I27: =COUNTIF('A3263'!AM:AM,"Verificar") -> 1 | T27: =COUNTIFS('A3042'!$AK:$AK,'Cooperados Alto Risco'!N27) -> 0 | U27: =COUNTIFS('A3043'!$AK:$AK,'Cooperados Alto Risco'!N27) -> 0 | V27: =COUNTIFS('A3054'!$AK:$AK,'Cooperados Alto Risco'!N27) -> 0 | W27: =COUNTIFS('A3059'!$AK:$AK,'Cooperados Alto Risco'!N27) -> 0 | X27: =COUNTIFS('A3060'!$AK:$AK,'Cooperados Alto Risco'!N27) -> 0 | Y27: =COUNTIFS('A3233'!$AK:$AK,'Cooperados Alto Risco'!N27) -> 0 | Z27: =COUNTIFS('A3261'!$AK:$AK,'Cooperados Alto Risco'!N27) -> 0 | AA27: =COUNTIFS('A3263'!$AK:$AK,'Cooperados Alto Risco'!N27) -> 0 | AB27: =COUNTIFS('A3320'!$AK:$AK,'Cooperados Alto Risco'!N27) -> 0 | AC27: =COUNTIFS('A3332'!$AK:$AK,'Cooperados Alto Risco'!N27) -> 0 | AD27: =COUNTIFS('A3333'!$AK:$AK,'Cooperados Alto Risco'!N27) -> 0 | AE27: =COUNTIFS('A3348'!$AK:$AK,'Cooperados Alto Risco'!N27) -> 0 | AF27: =COUNTIFS('A3349'!$AK:$AK,'Cooperados Alto Risco'!N27) -> 0 | AG27: =COUNTIFS('A3351'!$AK:$AK,'Cooperados Alto Risco'!N27) -> 0 | AH27: =COUNTIFS('A4001'!$AK:$AK,'Cooperados Alto Risco'!N27) -> 0 | AI27: =COUNTIFS('A4002'!$AK:$AK,'Cooperados Alto Risco'!N27) -> 0 | AJ27: =COUNTIFS('A4041'!$AK:$AK,'Cooperados Alto Risco'!N27) -> 0 | AK27: =COUNTIFS('A4155'!$AK:$AK,'Cooperados Alto Risco'!N27) -> 0 | AL27: =COUNTIFS('A4198'!$AK:$AK,'Cooperados Alto Risco'!N27) -> 0 | AM27: =COUNTIFS('A4221'!$AK:$AK,'Cooperados Alto Risco'!N27) -> 0 | AN27: =COUNTIFS('A4278'!$AK:$AK,'Cooperados Alto Risco'!N27) -> 0 | AO27: =COUNTIFS('A4332'!$AK:$AK,'Cooperados Alto Risco'!N27) -> 0 | AP27: =COUNTIFS('A4364'!$AK:$AK,'Cooperados Alto Risco'!N27) -> 0 | AQ27: =SUM(T27:AP27) -> 0
D28: Sicoob Cerrado | E28: 3320 | F28: ='Risco por Cooperativa'!H29 -> 2 | G28: =IFERROR((COUNTIF('A3320'!$AL:$AL,"Sim"))/F28,0) -> 0.5 | H28: =COUNTIF('A3320'!$AL:$AL,"Sim") -> 1 | I28: =COUNTIF('A3320'!AM:AM,"Verificar") -> 1 | S28: =SUM(S20:S27) -> 0 | T28: =IFERROR(SUM(T20:T27),0) -> 0 | U28: =IFERROR(SUM(U20:U27),0) -> 0 | V28: =IFERROR(SUM(V20:V27),0) -> 0 | W28: =IFERROR(SUM(W20:W27),0) -> 0 | X28: =IFERROR(SUM(X20:X27),0) -> 0 | Y28: =IFERROR(SUM(Y20:Y27),0) -> 0 | Z28: =IFERROR(SUM(Z20:Z27),0) -> 0 | AA28: =IFERROR(SUM(AA20:AA27),0) -> 0 | ... AQ28: =IFERROR(SUM(AQ20:AQ27),0) -> 0
D29: Sicoob Emprecred | E29: 3332 | F29: ='Risco por Cooperativa'!H30 -> 4 | G29: =IFERROR((COUNTIF('A3332'!$AL:$AL,"Sim"))/F29,0) -> 1 | H29: =COUNTIF('A3332'!$AL:$AL,"Sim") -> 4 | I29: =COUNTIF('A3332'!AM:AM,"Verificar") -> 0
D30: Sicob Secovicred | E30: 3333 | F30: ='Risco por Cooperativa'!H31 -> 4 | G30: =IFERROR((COUNTIF('A3333'!$AL:$AL,"Sim"))/F30,0) -> 1 | H30: =COUNTIF('A3333'!$AL:$AL,"Sim") -> 4 | I30: =COUNTIF('A3333'!AM:AM,"Verificar") -> 0
D31: Sicoob Juriscredcelg | E31: 3348 | F31: ='Risco por Cooperativa'!H32 -> 0 | G31: =IFERROR((COUNTIF('A3348'!$AL:$AL,"Sim"))/F31,0) -> 0 | H31: =COUNTIF('A3348'!$AL:$AL,"Sim") -> 0 | I31: =COUNTIF('A3348'!AM:AM,"Verificar") -> 0
D32: Sicoob Credicer | E32: 3349 | F32: ='Risco por Cooperativa'!H33 -> 1 | G32: =IFERROR((COUNTIF('A3349'!$AL:$AL,"Sim"))/F32,0) -> 1 | H32: =COUNTIF('A3349'!$AL:$AL,"Sim") -> 1 | I32: =COUNTIF('A3349'!AM:AM,"Verificar") -> 0
D33: Sicoob Crediadag | E33: 3351 | F33: ='Risco por Cooperativa'!H34 -> 1 | G33: =IFERROR((COUNTIF('A3351'!$AL:$AL,"Sim"))/F33,0) -> 0 | H33: =COUNTIF('A3351'!$AL:$AL,"Sim") -> 0 | I33: =COUNTIF('A3351'!AM:AM,"Verificar") -> 1
D34: Sicoob Empresarial | E34: 3343 | F34: ='Risco por Cooperativa'!H35 -> 0 | G34: =IFERROR((COUNTIF('A3343'!$AL:$AL,"Sim"))/F34,0) -> 0 | H34: =COUNTIF('A3343'!$AL:$AL,"Sim") -> 0 | I34: =COUNTIF('A3343'!AM:AM,"Verificar") -> 0
D35: Sicoob Cooprem | E35: 3350 | F35: ='Risco por Cooperativa'!H36 -> 1 | G35: =IFERROR((COUNTIF('A3350'!$AL:$AL,"Sim"))/F35,0) -> 1 | H35: =COUNTIF('A3350'!$AL:$AL,"Sim") -> 1 | I35: =COUNTIF('A3350'!AM:AM,"Verificar") -> 0
D36: Sicoob Credi-Comigo | E36: 3336 | F36: ='Risco por Cooperativa'!H37 -> 0 | G36: =IFERROR((COUNTIF('A3336'!$AL:$AL,"Sim"))/F36,0) -> 0 | H36: =COUNTIF('A3336'!$AL:$AL,"Sim") -> 0 | I36: =COUNTIF('A3336'!AM:AM,"Verificar") -> 0
D37: Sicoob Credigóias | E37: 3058 | F37: ='Risco por Cooperativa'!H38 -> 1 | G37: =IFERROR((COUNTIF('A3058'!$AL:$AL,"Sim"))/F37,0) -> 0 | H37: =COUNTIF('A3058'!$AL:$AL,"Sim") -> 0 | I37: =COUNTIF('A3058'!AM:AM,"Verificar") -> 1
D38: Sicoob Coopercred | E38: 3055 | F38: ='Risco por Cooperativa'!H39 -> 0 | G38: =IFERROR((COUNTIF('A3055'!$AL:$AL,"Sim"))/F38,0) -> 0 | H38: =COUNTIF('A3055'!$AL:$AL,"Sim") -> 0 | I38: =COUNTIF('A3055'!AM:AM,"Verificar") -> 0
D39: Sicoob Unicidades | E39: 5014 | F39: ='Risco por Cooperativa'!H40 -> 1 | G39: =IFERROR((COUNTIF('A5014'!$AL:$AL,"Sim"))/F39,0) -> 1 | H39: =COUNTIF('A5014'!$AL:$AL,"Sim") -> 1 | I39: =COUNTIF('A5014'!AM:AM,"Verificar") -> 0
D40: Sicoob Mineiros | E40: 3056 | F40: ='Risco por Cooperativa'!H41 -> 2 | G40: =IFERROR((COUNTIF('A3056'!$AL:$AL,"Sim"))/F40,0) -> 1.5 | H40: =COUNTIF('A3056'!$AL:$AL,"Sim") -> 3 | I40: =COUNTIF('A3056'!AM:AM,"Verificar") -> 0
D41: Sicoob Centro Oeste BR | E41: 3300 | F41: ='Risco por Cooperativa'!H42 -> 2 | G41: =IFERROR((COUNTIF('A3300'!$AL:$AL,"Sim"))/F41,0) -> 1 | H41: =COUNTIF('A3300'!$AL:$AL,"Sim") -> 2 | I41: =COUNTIF('A3300'!AM:AM,"Verificar") -> 0
D42: Sicoob Executivo | E42: 4001 | F42: ='Risco por Cooperativa'!H43 -> 0 | G42: =IFERROR((COUNTIF('A4001'!$AL:$AL,"Sim"))/F42,0) -> 0 | H42: =COUNTIF('A4001'!$AL:$AL,"Sim") -> 0 | I42: =COUNTIF('A4001'!AM:AM,"Verificar") -> 0
D43: Sicoob Judiciário | E43: 4002 | F43: ='Risco por Cooperativa'!H44 -> 0 | G43: =IFERROR((COUNTIF('A4002'!$AL:$AL,"Sim"))/F43,0) -> 0 | H43: =COUNTIF('A4002'!$AL:$AL,"Sim") -> 0 | I43: =COUNTIF('A4002'!AM:AM,"Verificar") -> 0
D44: Sicoob Credijustra | E44: 4041 | F44: ='Risco por Cooperativa'!H45 -> 0 | G44: =IFERROR((COUNTIF('A4041'!$AL:$AL,"Sim"))/F44,0) -> 0 | H44: =COUNTIF('A4041'!$AL:$AL,"Sim") -> 0 | I44: =COUNTIF('A4041'!AM:AM,"Verificar") -> 0
